Workbook
Name cds: cds!$I$3:$N$4708
Name dbbbg: db00!$A$3:$N$1611
Name idyield: yieldid!$A$3:$AP$4131

Sheet Sheet1
B2: Start Date | C2: 39448 | O2: Start Date | P2: 39448 | R2: Security | S2: IDCPIY Index
B3: End Date | O3: End Date | R3: Start Date | S3: 38807
R4: End Date | S4: 46081
C5: GT10 @BGN Govt | D5: GT02 @BGN Govt | E5: VIX Index | F5: MOVE Index | G5: DXY Curncy | H5: IHN+1M BGN Curncy | I5: IHN+12M BGN Curncy | J5: IDR REGN Curncy | K5: GB03 @BGN Govt | L5: XAU BGN Curncy | P5: IDCPIY Index | R5: Period | S5: M
C6: =_xll.BFieldInfo(C$7) -> #NAME? | D6: =_xll.BFieldInfo(D$7) -> #NAME? | E6: =_xll.BFieldInfo(E$7) -> #NAME? | F6: =_xll.BFieldInfo(F$7) -> #NAME? | G6: =_xll.BFieldInfo(G$7) -> #NAME? | H6: =_xll.BFieldInfo(H$7) -> #NAME? | I6: =_xll.BFieldInfo(I$7) -> #NAME? | J6: =_xll.BFieldInfo(J$7) -> #NAME? | ... L6: =_xll.BFieldInfo(L$7) -> #NAME? | P6: =_xll.BFieldInfo(P$7) -> #NAME?
B7: Dates | C7: YLD_YTM_MID | D7: YLD_YTM_MID | E7: PX_LAST | F7: PX_LAST | G7: PX_LAST | H7: PX_LAST | I7: PX_LAST | J7: PX_LAST | K7: YLD_YTM_MID | L7: PX_LAST | O7: Dates | P7: PX_LAST | R7: Date | S7: PX_MID | T7: BN_SURVEY_AVERAGE
B8: {=_xll.BDH(C$5,C$7,$C2,$C3,"Dir=V","CDR=5D","Days=A","Dts=S")} -> #NAME? | D8: {=_xll.BDH(D$5,D$7,$C2,$C3,"Dir=V","CDR=5D","Days=A","Dts=H")} -> #NAME? | E8: {=_xll.BDH(E$5,E$7,$C2,$C3,"Dir=V","CDR=5D","Days=A","Dts=H")} -> #NAME? | F8: {=_xll.BDH(F$5,F$7,$C2,$C3,"Dir=V","CDR=5D","Days=A","Dts=H")} -> #NAME? | G8: {=_xll.BDH(G$5,G$7,$C2,$C3,"Dir=V","CDR=5D","Days=A","Dts=H")} -> #NAME? | H8: {=_xll.BDH(H$5,H$7,$C2,$C3,"Dir=V","CDR=5D","Days=A","Dts=H")} -> #NAME? | I8: {=_xll.BDH(I$5,I$7,$C2,$C3,"Dir=V","CDR=5D","Days=A","Dts=H")} -> #NAME? | J8: {=_xll.BDH(J$5,J$7,$C2,$C3,"Dir=V","CDR=5D","Days=A","Dts=H")} -> #NAME? | K8: {=_xll.BDH(K$5,K$7,$C2,$C3,"Dir=V","CDR=5D","Days=A","Dts=H")} -> #NAME? | L8: {=_xll.BDH(L$5,L$7,$C2,$C3,"Dir=V","CDR=5D","Days=A","Dts=H")} -> #NAME? | O8: {=_xll.BDH(P$5,P$7,$C2,$C3,"Dir=V","CDR=5D","Days=A","Dts=S")} -> #NAME? | R8: {=_xll.BDH(S2,S7:T7,S3,S4,"Dir=V","Dts=S","Sort=A","Quote=C","QtTyp=P","Days=T",CONCATENATE("Per=c",S5),"DtFmt=D","UseDPDF=Y")} -> #NAME?

Sheet Sheet2
B1: GT10 @BGN Govt | C1: GT02 @BGN Govt | D1: VIX Index | E1: MOVE Index | F1: DXY Curncy | G1: IHN+1M BGN Curncy | H1: IHN+12M BGN Curncy | I1: IDR REGN Curncy | J1: GB03 @BGN Govt | K1: XAU BGN Curncy | N1: IDCPIY Index
A2: Dates | B2: YLD_YTM_MID | C2: YLD_YTM_MID | D2: PX_LAST | E2: PX_LAST | F2: PX_LAST | G2: PX_LAST | H2: PX_LAST | I2: PX_LAST | J2: YLD_YTM_MID | K2: PX_LAST | M2: Dates | N2: PX_LAST
A3: 39448 | B3: 4.025 | C3: 3.05 | D3: 22.5 | E3: 145.4 | F3: 76.648 | G3: 9400 | H3: 9585 | I3: 9393 | J3: 3.332 | K3: 833.7 | M3: 39448 | N3: 6.59
A4: 39449 | B4: 3.905 | C4: 2.88 | D4: 23.17 | E4: 148.7 | F4: 75.972 | G4: 9385 | H4: 9595 | I4: 9386 | J4: 3.254 | K4: 857.5 | M4: 39449 | N4: 6.59
A5: 39450 | B5: 3.894 | C5: 2.815 | D5: 22.49 | E5: 145.6 | F5: 75.889 | G5: 9420 | H5: 9630 | I5: 9405 | J5: 3.223 | K5: 864.9 | M5: 39450 | N5: 6.59
A6: 39451 | B6: 3.867 | C6: 2.748 | D6: 23.94 | E6: 138.1 | F6: 75.793 | G6: 9470 | H6: 9645 | I6: 9422 | J6: 3.191 | K6: 859.6 | M6: 39451 | N6: 6.59
A7: 39454 | B7: 3.833 | C7: 2.747 | D7: 23.79 | E7: 130.9 | F7: 76.174 | G7: 9475 | H7: 9668 | I7: 9455 | J7: 3.242 | K7: 858.1 | M7: 39454 | N7: 6.59
A8: 39455 | B8: 3.784 | C8: 2.682 | D8: 25.43 | E8: 124 | F8: 76.111 | G8: 9480 | H8: 9678 | I8: 9455 | J8: 3.218 | K8: 878 | M8: 39455 | N8: 6.59
A9: 39456 | B9: 3.823 | C9: 2.721 | D9: 24.12 | E9: 128 | F9: 76.419 | G9: 9465 | H9: 9680 | I9: 9458 | J9: 3.233 | K9: 878.8 | M9: 39456 | N9: 6.59
A10: 39457 | B10: 3.886 | C10: 2.696 | D10: 23.45 | E10: 125.3 | F10: 75.934 | G10: 9470 | H10: 9680 | I10: 9458 | J10: 3.212 | K10: 893.3 | M10: 39457 | N10: 6.59
A11: 39458 | B11: 3.785 | C11: 2.555 | D11: 23.68 | E11: 130.9 | F11: 75.978 | G11: 9463 | H11: 9660 | I11: 9433 | J11: 3.098 | K11: 895.4 | M11: 39458 | N11: 6.59
A12: 39461 | B12: 3.767 | C12: 2.554 | D12: 22.9 | E12: 130.565 | F12: 75.613 | G12: 9445 | H12: 9650 | I12: 9434 | J12: 3.16 | K12: 904 | M12: 39461 | N12: 6.59
A13: 39462 | B13: 3.677 | C13: 2.48 | D13: 23.34 | E13: 131.9 | F13: 75.574 | G13: 9483 | H13: 9685 | I13: 9438 | J13: 3.156 | K13: 887.9 | M13: 39462 | N13: 6.59
A14: 39463 | B14: 3.736 | C14: 2.503 | D14: 24.38 | E14: 133 | F14: 76.258 | G14: 9470 | H14: 9675 | I14: 9437 | J14: 3.13 | K14: 877 | M14: 39463 | N14: 6.59
... A4743: 46083 | B4743: 3.961 | C4743: 3.387 | D4743: 19.86 | E4743: 73.38 | F4743: 98.112 | G4743: 16879 | H4743: 17094 | I4743: 16855 | J4743: 3.66 | K4743: 5379.03 | M4743: 46083 | N4743: 4.76

Sheet Sheet3
A2: Security | B2: IDCPIY Index
A3: Start Date | B3: 38807
A4: End Date | B4: 46081
A5: Period | B5: M
A7: Date | B7: PX_MID | C7: BN_SURVEY_AVERAGE
A8: 38807 | B8: 15.74 | C8: 16.15
A9: 38837 | B9: 15.4 | C9: 15.67
A10: 38868 | B10: 15.6 | C10: 15.57
A11: 38898 | B11: 15.53 | C11: 15.52
A12: 38929 | B12: 15.15 | C12: 15.26
A13: 38960 | B13: 14.9 | C13: 14.94
A14: 38990 | B14: 14.55 | C14: 14.57
A15: 39021 | B15: 6.29 | C15: 6.21
A16: 39051 | B16: 5.27 | C16: 5.68
A17: 39082 | B17: 6.6 | C17: 5.91
A18: 39113 | B18: 6.26 | C18: 6.06
A19: 39141 | B19: 6.3 | C19: 6.76
... A247: 46081 | B247: 4.76 | C247: 4.24

Sheet db00
A1: LAGGED 1D | B1: GT10 @BGN Govt | C1: GT02 @BGN Govt | D1: VIX Index | E1: MOVE Index | F1: DXY Curncy | G1: IHN+1M BGN Curncy | H1: IHN+12M BGN Curncy | I1: IDR REGN Curncy | J1: GB03 @BGN Govt | K1: XAU BGN Curncy | L1: IDCPIY Index | M1: ndf_1m_points_pct | N1: ndf_12m_points_pct
A2: Dates | B2: YLD_YTM_MID | C2: YLD_YTM_MID | D2: PX_LAST | E2: PX_LAST | F2: PX_LAST | G2: PX_LAST | H2: PX_LAST | I2: PX_LAST | J2: YLD_YTM_MID | K2: PX_LAST | L2: PX_LAST
A3: dates | B3: ust_10y | C3: ust_2y | D3: vix | E3: move | F3: dxy | I3: idr_regn | J3: ust_3m | K3: xau_gold | L3: inflation | M3: ndf_1m | N3: ndf_12m | P3: lagged 1 day due to time difference
A4: 43832 | B4: 1.919 | C4: 1.571 | D4: 13.78 | E4: 58.28 | F4: 96.445 | G4: 13877 | H4: 14410 | I4: 13866 | J4: 1.549 | K4: 1517.29 | L4: 2.72 | M4: =((G4-I4)/I4)*100 -> 0.079330737 | N4: =((H4-I4)/I4)*100 -> 3.9232655
A5: 43833 | B5: 1.878 | C5: 1.57 | D5: 12.47 | E5: 57.2 | F5: 96.846 | G5: 13910 | H5: 14416 | I5: 13893 | J5: 1.528 | K5: 1529.13 | L5: 2.72 | M5: =((G5-I5)/I5)*100 -> 0.12236378 | N5: =((H5-I5)/I5)*100 -> 3.7644857
A6: 43836 | B6: 1.789 | C6: 1.528 | D6: 14.02 | E6: 60.12 | F6: 96.838 | G6: 13981 | H6: 14505 | I6: 13930 | J6: 1.513 | K6: 1552.2 | L6: 2.72 | M6: =((G6-I6)/I6)*100 -> 0.3661163 | N6: =((H6-I6)/I6)*100 -> 4.1277818
A7: 43837 | B7: 1.81 | C7: 1.546 | D7: 13.85 | E7: 62.79 | F7: 96.671 | G7: 13965 | H7: 14495 | I7: 13944 | J7: 1.528 | K7: 1565.74 | L7: 2.72 | M7: =((G7-I7)/I7)*100 -> 0.15060241 | N7: =((H7-I7)/I7)*100 -> 3.9515204
A8: 43838 | B8: 1.819 | C8: 1.542 | D8: 13.79 | E8: 62.63 | F8: 97.005 | G8: 13943 | H8: 14457 | I8: 13878 | J8: 1.53 | K8: 1574.37 | L8: 2.72 | M8: =((G8-I8)/I8)*100 -> 0.4683672 | N8: =((H8-I8)/I8)*100 -> 4.1720709
A9: 43839 | B9: 1.875 | C9: 1.584 | D9: 13.45 | E9: 60.49 | F9: 97.299 | G9: 13879 | H9: 14406 | I9: 13900 | J9: 1.532 | K9: 1556.42 | L9: 2.72 | M9: =((G9-I9)/I9)*100 -> -0.15107914 | N9: =((H9-I9)/I9)*100 -> 3.6402878
A10: 43840 | B10: 1.856 | C10: 1.58 | D10: 12.54 | E10: 57.66 | F10: 97.45 | G10: 13873 | H10: 14398 | I10: 13854 | J10: 1.532 | K10: 1552.32 | L10: 2.72 | M10: =((G10-I10)/I10)*100 -> 0.13714451 | N10: =((H10-I10)/I10)*100 -> 3.9266638
A11: 43843 | B11: 1.821 | C11: 1.571 | D11: 12.56 | E11: 53.32 | F11: 97.356 | G11: 13768 | H11: 14329 | I11: 13772 | J11: 1.533 | K11: 1562.34 | L11: 2.72 | M11: =((G11-I11)/I11)*100 -> -0.029044438 | N11: =((H11-I11)/I11)*100 -> 4.044438
A12: 43844 | B12: 1.847 | C12: 1.586 | D12: 12.32 | E12: 53.27 | F12: 97.345 | G12: 13691 | H12: 14159 | I12: 13673 | J12: 1.546 | K12: 1547.88 | L12: 2.72 | M12: =((G12-I12)/I12)*100 -> 0.13164631 | N12: =((H12-I12)/I12)*100 -> 3.5544504
A13: 43845 | B13: 1.812 | C13: 1.572 | D13: 12.39 | E13: 52.35 | F13: 97.372 | G13: 13725 | H13: 14202 | I13: 13680 | J13: 1.562 | K13: 1546.39 | L13: 2.72 | M13: =((G13-I13)/I13)*100 -> 0.32894737 | N13: =((H13-I13)/I13)*100 -> 3.8157895
A14: 43846 | B14: 1.784 | C14: 1.555 | D14: 12.42 | E14: 50.54 | F14: 97.229 | G14: 13724 | H14: 14193 | I14: 13695 | J14: 1.56 | K14: 1556.25 | L14: 2.72 | M14: =((G14-I14)/I14)*100 -> 0.21175612 | N14: =((H14-I14)/I14)*100 -> 3.6363636
A15: 43847 | B15: 1.808 | C15: 1.567 | D15: 12.32 | E15: 50.37 | F15: 97.32 | G15: 13673 | H15: 14137 | I15: 13643 | J15: 1.549 | K15: 1552.51 | L15: 2.72 | M15: =((G15-I15)/I15)*100 -> 0.21989299 | N15: =((H15-I15)/I15)*100 -> 3.6209045
... A1611: 46083 | B1611: 3.941 | C1611: 3.378 | D1611: 19.86 | E1611: 73.38 | F1611: 97.608 | G1611: 16803 | H1611: 17020 | I1611: 16771 | J1611: 3.661 | K1611: 5278.93 | L1611: 4.76 | M1611: =((G1611-I1611)/I1611)*100 -> 0.19080556 | N1611: =((H1611-I1611)/I1611)*100 -> 1.4847057
B1612: 3.961 | C1612: 3.387 | D1612: 19.86 | E1612: 73.38 | F1612: 98.112 | G1612: 16879 | H1612: 17094 | I1612: 16855 | J1612: 3.66 | K1612: 5379.03

Sheet cds
A1: dates | B1: CDS 10Y | C1: CDS 1Y | D1: CDS 3Y | E1: CDS 5Y | F1: CDS 7Y | H1: LAGGED 1D | I1: dates | J1: CDS 10Y | K1: CDS 1Y | L1: CDS 3Y | M1: CDS 5Y | N1: CDS 7Y
A2: 39448 | B2: 211.1 | C2: 93.1 | D2: 122.9 | E2: 153.5 | F2: 180.9 | I2: 39448
A3: 39449 | B3: 213.7 | C3: 94.7 | D3: 125 | E3: 156.1 | F3: 183.5 | I3: 39449 | J3: 211.1 | K3: 93.1 | L3: 122.9 | M3: 153.5 | N3: 180.9
A4: 39450 | B4: 223 | C4: 101.8 | D4: 134.4 | E4: 167.8 | F4: 190.7 | I4: 39450 | J4: 213.7 | K4: 94.7 | L4: 125 | M4: 156.1 | N4: 183.5
A5: 39451 | B5: 224.5 | C5: 106.3 | D5: 140.3 | E5: 175.2 | F5: 196.6 | I5: 39451 | J5: 223 | K5: 101.8 | L5: 134.4 | M5: 167.8 | N5: 190.7
A6: 39454 | B6: 238.2 | C6: 108 | D6: 143 | E6: 184.8 | F6: 212.4 | I6: 39454 | J6: 224.5 | K6: 106.3 | L6: 140.3 | M6: 175.2 | N6: 196.6
A7: 39455 | B7: 239.6 | C7: 105.8 | D7: 142 | E7: 184.6 | F7: 212.9 | I7: 39455 | J7: 238.2 | K7: 108 | L7: 143 | M7: 184.8 | N7: 212.4
A8: 39456 | B8: 246.2 | C8: 105 | D8: 143 | E8: 193.1 | F8: 222.9 | I8: 39456 | J8: 239.6 | K8: 105.8 | L8: 142 | M8: 184.6 | N8: 212.9
A9: 39457 | B9: 262.7 | C9: 107.5 | D9: 149.3 | E9: 207.1 | F9: 218.8 | I9: 39457 | J9: 246.2 | K9: 105 | L9: 143 | M9: 193.1 | N9: 222.9
A10: 39458 | B10: 256 | C10: 110.2 | D10: 152 | E10: 205.5 | F10: 235.5 | I10: 39458 | J10: 262.7 | K10: 107.5 | L10: 149.3 | M10: 207.1 | N10: 218.8
A11: 39461 | B11: 261.8 | C11: 112.4 | D11: 155 | E11: 205.8 | F11: 236.6 | I11: 39461 | J11: 256 | K11: 110.2 | L11: 152 | M11: 205.5 | N11: 235.5
A12: 39462 | B12: 260 | C12: 106.8 | D12: 154.5 | E12: 206 | F12: 227.7 | I12: 39462 | J12: 261.8 | K12: 112.4 | L12: 155 | M12: 205.8 | N12: 236.6
A13: 39463 | B13: 270 | C13: 120 | D13: 162 | E13: 214 | F13: 233 | I13: 39463 | J13: 260 | K13: 106.8 | L13: 154.5 | M13: 206 | N13: 227.7
A14: 39464 | B14: 265.7 | C14: 115 | D14: 162.7 | E14: 213.5 | F14: 237 | I14: 39464 | J14: 270 | K14: 120 | L14: 162 | M14: 214 | N14: 233
... A4708: 46080 | B4708: 133.34 | C4708: 31.335 | D4708: 56.18 | E4708: 83.625 | F4708: 106.725 | I4708: 46080 | J4708: 131.715 | K4708: 28.74 | L4708: 54.335 | M4708: 81.175 | N4708: 104.77
J4709: 133.34 | K4709: 31.335 | L4709: 56.18 | M4709: 83.625 | N4709: 106.725

Sheet yieldid
A1: tanggal | B1: 0.08 | C1: 1 | D1: 2 | E1: 3 | F1: 4 | G1: 5 | H1: 6 | I1: 7 | J1: 8 | K1: 9 | L1: 10 | M1: 11 | N1: 12 | O1: 13 | P1: 14 | Q1: 15 | R1: 16 | S1: 17 | T1: 18 | U1: 19 | V1: 20 | W1: 21 | X1: 22 | Y1: 23 | Z1: 24 | AA1: 25 | AB1: 26 | AC1: 27 | AD1: 28 | AE1: 29 | AF1: 30 | AG1: 31 | AH1: 32 | AI1: 33 | AJ1: 34 | AK1: 35 | AL1: 36 | AM1: 37 | AN1: 38 | AO1: 40 | AP1: 39
A2: 39783
A3: 39784 | B3: 11.1608 | C3: 13.1428 | D3: 14.2631 | E3: 14.8053 | F3: 15.0598 | G3: 15.1813 | H3: 15.2478 | I3: 15.296 | J3: 15.3412 | K3: 15.3877 | L3: 15.4355 | M3: 15.483 | N3: 15.5284 | O3: 15.5703 | P3: 15.6078 | Q3: 15.6405 | R3: 15.6685 | S3: 15.692 | T3: 15.7114 | U3: 15.7272 | V3: 15.74 | W3: 15.7503 | X3: 15.7584 | Y3: 15.7648 | Z3: 15.7698 | AA3: 15.7737 | AB3: 15.7767 | AC3: 15.779 | AD3: 15.7807 | AE3: 15.7821 | AF3: 15.7831
A4: 39785 | B4: 11.2202 | C4: 13.4662 | D4: 14.893 | E4: 15.3152 | F4: 15.3827 | G4: 15.367 | H4: 15.3487 | I4: 15.3455 | J4: 15.3581 | K4: 15.3834 | L4: 15.418 | M4: 15.4589 | N4: 15.5037 | O4: 15.5507 | P4: 15.5984 | Q4: 15.6457 | R4: 15.6918 | S4: 15.7362 | T4: 15.7785 | U4: 15.8184 | V4: 15.8558 | W4: 15.8906 | X4: 15.9229 | Y4: 15.9526 | Z4: 15.9799 | AA4: 16.0049 | AB4: 16.0277 | AC4: 16.0484 | AD4: 16.0672 | AE4: 16.0842 | AF4: 16.0996
A5: 39786 | B5: 11.0704 | C5: 13.4975 | D5: 14.701 | E5: 15.1837 | F5: 15.3492 | G5: 15.3899 | H5: 15.3928 | I5: 15.3938 | J5: 15.4047 | K5: 15.4272 | L5: 15.4593 | M5: 15.4976 | N5: 15.5393 | O5: 15.5821 | P5: 15.6241 | Q5: 15.6642 | R5: 15.7018 | S5: 15.7364 | T5: 15.768 | U5: 15.7965 | V5: 15.8219 | W5: 15.8446 | X5: 15.8646 | Y5: 15.8823 | Z5: 15.8978 | AA5: 15.9113 | AB5: 15.9231 | AC5: 15.9334 | AD5: 15.9423 | AE5: 15.95 | AF5: 15.9567
A6: 39787 | B6: 10.7434 | C6: 13.2896 | D6: 14.1368 | E6: 14.3185 | F6: 14.3461 | G6: 14.3732 | H6: 14.4266 | I6: 14.4967 | J6: 14.5697 | K6: 14.6362 | L6: 14.6919 | M6: 14.7358 | N6: 14.769 | O6: 14.7932 | P6: 14.8105 | Q6: 14.8226 | R6: 14.8309 | S6: 14.8365 | T6: 14.8402 | U6: 14.8427 | V6: 14.8444 | W6: 14.8454 | X6: 14.8461 | Y6: 14.8466 | Z6: 14.8469 | AA6: 14.8471 | AB6: 14.8472 | AC6: 14.8472 | AD6: 14.8473 | AE6: 14.8473 | AF6: 14.8473
A7: 39791 | B7: 10.9675 | C7: 12.8385 | D7: 13.7358 | E7: 13.9833 | F7: 14.0397 | G7: 14.0509 | H7: 14.0528 | I7: 14.053 | J7: 14.053 | K7: 14.053 | L7: 14.053 | M7: 14.053 | N7: 14.053 | O7: 14.053 | P7: 14.053 | Q7: 14.053 | R7: 14.053 | S7: 14.053 | T7: 14.053 | U7: 14.053 | V7: 14.053 | W7: 14.053 | X7: 14.053 | Y7: 14.053 | Z7: 14.053 | AA7: 14.053 | AB7: 14.053 | AC7: 14.053 | AD7: 14.053 | AE7: 14.053 | AF7: 14.053
A8: 39793 | B8: 10.9039 | C8: 12.5037 | D8: 12.696 | E8: 12.6465 | F8: 12.6462 | G8: 12.7008 | H8: 12.7751 | I8: 12.8456 | J8: 12.9026 | K8: 12.9448 | L8: 12.9743 | M8: 12.9942 | N8: 13.0073 | O8: 13.0158 | P8: 13.0211 | Q8: 13.0245 | R8: 13.0266 | S8: 13.0279 | T8: 13.0286 | U8: 13.0291 | V8: 13.0294 | W8: 13.0296 | X8: 13.0297 | Y8: 13.0298 | Z8: 13.0298 | AA8: 13.0298 | AB8: 13.0298 | AC8: 13.0299 | AD8: 13.0299 | AE8: 13.0299 | AF8: 13.0299
A9: 39794 | B9: 10.9463 | C9: 12.4322 | D9: 12.8107 | E9: 12.8879 | F9: 12.9124 | G9: 12.9362 | H9: 12.9659 | I9: 12.9992 | J9: 13.0331 | K9: 13.0655 | L9: 13.0953 | M9: 13.1218 | N9: 13.145 | O9: 13.1648 | P9: 13.1816 | Q9: 13.1956 | R9: 13.2073 | S9: 13.217 | T9: 13.2249 | U9: 13.2313 | V9: 13.2365 | W9: 13.2408 | X9: 13.2442 | Y9: 13.2469 | Z9: 13.2491 | AA9: 13.2508 | AB9: 13.2522 | AC9: 13.2533 | AD9: 13.2542 | AE9: 13.2549 | AF9: 13.2555
A10: 39797 | B10: 10.9534 | C10: 12.3555 | D10: 12.6911 | E10: 12.79 | F10: 12.8577 | G10: 12.9222 | H10: 12.9818 | I10: 13.0333 | J10: 13.0755 | K10: 13.1087 | L10: 13.1343 | M10: 13.1535 | N10: 13.1677 | O10: 13.1781 | P10: 13.1857 | Q10: 13.1911 | R10: 13.195 | S10: 13.1977 | T10: 13.1997 | U10: 13.2011 | V10: 13.202 | W10: 13.2027 | X10: 13.2031 | Y10: 13.2035 | Z10: 13.2037 | AA10: 13.2038 | AB10: 13.2039 | AC10: 13.204 | AD10: 13.2041 | AE10: 13.2041 | AF10: 13.2041
A11: 39798 | B11: 10.8981 | C11: 12.4337 | D11: 12.6417 | E11: 12.6798 | F11: 12.7252 | G11: 12.7685 | H11: 12.7993 | I11: 12.8177 | J11: 12.8276 | K11: 12.8326 | L11: 12.835 | M11: 12.8361 | N11: 12.8366 | O11: 12.8368 | P11: 12.8369 | Q11: 12.8369 | R11: 12.8369 | S11: 12.8369 | T11: 12.8369 | U11: 12.8369 | V11: 12.8369 | W11: 12.8369 | X11: 12.8369 | Y11: 12.8369 | Z11: 12.8369 | AA11: 12.8369 | AB11: 12.8369 | AC11: 12.8369 | AD11: 12.8369 | AE11: 12.8369 | AF11: 12.8369
A12: 39799 | B12: 10.9075 | C12: 12.365 | D12: 12.4779 | E12: 12.4694 | F12: 12.5181 | G12: 12.5876 | H12: 12.6471 | I12: 12.6882 | J12: 12.7134 | K12: 12.7278 | L12: 12.7355 | M12: 12.7395 | N12: 12.7415 | O12: 12.7425 | P12: 12.743 | Q12: 12.7432 | R12: 12.7433 | S12: 12.7434 | T12: 12.7434 | U12: 12.7434 | V12: 12.7434 | W12: 12.7434 | X12: 12.7434 | Y12: 12.7434 | Z12: 12.7434 | AA12: 12.7434 | AB12: 12.7434 | AC12: 12.7434 | AD12: 12.7434 | AE12: 12.7434 | AF12: 12.7434
A13: 39800 | B13: 11.0535 | C13: 11.3439 | D13: 11.4508 | E13: 11.5235 | F13: 11.5975 | G13: 11.6691 | H13: 11.7307 | I13: 11.7793 | J13: 11.815 | K13: 11.8401 | L13: 11.857 | M13: 11.8681 | N13: 11.8752 | O13: 11.8797 | P13: 11.8824 | Q13: 11.8841 | R13: 11.8851 | S13: 11.8857 | T13: 11.886 | U13: 11.8862 | V13: 11.8864 | W13: 11.8864 | X13: 11.8865 | Y13: 11.8865 | Z13: 11.8865 | AA13: 11.8865 | AB13: 11.8865 | AC13: 11.8865 | AD13: 11.8865 | AE13: 11.8865 | AF13: 11.8865
A14: 39801 | B14: 10.979 | C14: 11.2831 | D14: 11.2824 | E14: 11.3316 | F14: 11.405 | G14: 11.4657 | H14: 11.5052 | I14: 11.5279 | J14: 11.5398 | K14: 11.5458 | L14: 11.5486 | M14: 11.5499 | N14: 11.5505 | O14: 11.5508 | P14: 11.5509 | Q14: 11.5509 | R14: 11.551 | S14: 11.551 | T14: 11.551 | U14: 11.551 | V14: 11.551 | W14: 11.551 | X14: 11.551 | Y14: 11.551 | Z14: 11.551 | AA14: 11.551 | AB14: 11.551 | AC14: 11.551 | AD14: 11.551 | AE14: 11.551 | AF14: 11.551
... A4116: 46062 | B4116: 4.450531 | C4116: 4.778996 | D4116: 5.087282 | E4116: 5.350268 | F4116: 5.573823 | G4116: 5.763145 | H4116: 5.922833 | I4116: 6.056947 | J4116: 6.169067 | K4116: 6.262342 | L4116: 6.339541 | M4116: 6.403089 | N4116: 6.455108 | O4116: 6.497449 | P4116: 6.531724 | Q4116: 6.55933 | R4116: 6.581478 | S4116: 6.599208 | T4116: 6.613417 | U4116: 6.624869 | V4116: 6.634214 | W4116: 6.642003 | X4116: 6.648698 | Y4116: 6.654685 | Z4116: 6.660281 | AA4116: 6.665746 | AB4116: 6.671291 | AC4116: 6.677079 | AD4116: 6.683241 | AE4116: 6.689872 | AF4116: 6.69704
A4117: 46059 | B4117: 4.499197 | C4117: 4.850022 | D4117: 5.175878 | E4117: 5.450759 | F4117: 5.681742 | G4117: 5.875018 | H4117: 6.036004 | I4117: 6.169421 | J4117: 6.279385 | K4117: 6.369474 | L4117: 6.44279 | M4117: 6.502023 | N4117: 6.549491 | O4117: 6.587194 | P4117: 6.616849 | Q4117: 6.639927 | R4117: 6.657681 | S4117: 6.671178 | T4117: 6.68132 | U4117: 6.688868 | V4117: 6.694456 | W4117: 6.698616 | X4117: 6.701784 | Y4117: 6.704319 | Z4117: 6.70651 | AA4117: 6.70859 | AB4117: 6.71074 | AC4117: 6.713102 | AD4117: 6.71578 | AE4117: 6.718849 | AF4117: 6.72236 | AG4117: 6.726344 | AH4117: 6.730813 | AI4117: 6.735768 | AJ4117: 6.741197 | AK4117: 6.74708 | AL4117: 6.753392 | AM4117: 6.760102 | AN4117: 6.767174 | AO4117: 6.782259 | AP4117: 6.774573
A4118: 46063 | B4118: 4.543865 | C4118: 4.869225 | D4118: 5.175328 | E4118: 5.436922 | F4118: 5.659503 | G4118: 5.847984 | H4118: 6.006749 | I4118: 6.139707 | J4118: 6.250337 | K4118: 6.341728 | L4118: 6.416621 | M4118: 6.47744 | N4118: 6.526328 | O4118: 6.565171 | P4118: 6.595629 | Q4118: 6.619154 | R4118: 6.637016 | S4118: 6.650321 | T4118: 6.660029 | U4118: 6.666969 | V4118: 6.671851 | W4118: 6.675287 | X4118: 6.677792 | Y4118: 6.679804 | Z4118: 6.681687 | AA4118: 6.683742 | AB4118: 6.686216 | AC4118: 6.689307 | AD4118: 6.693169 | AE4118: 6.697921 | AF4118: 6.703651 | AG4118: 6.710416 | AH4118: 6.718252 | AI4118: 6.727175 | AJ4118: 6.737183 | AK4118: 6.74826 | AL4118: 6.760378 | AM4118: 6.773499 | AN4118: 6.787579 | AO4118: 6.818404 | AP4118: 6.802566
A4119: 46064 | B4119: 4.503236 | C4119: 4.851799 | D4119: 5.175061 | E4119: 5.447439 | F4119: 5.676171 | G4119: 5.867559 | H4119: 6.02708 | I4119: 6.159485 | J4119: 6.268892 | K4119: 6.358858 | L4119: 6.432455 | M4119: 6.492328 | N4119: 6.540747 | O4119: 6.579659 | P4119: 6.610727 | Q4119: 6.635368 | R4119: 6.654786 | S4119: 6.669998 | T4119: 6.681861 | U4119: 6.691096 | V4119: 6.698302 | W4119: 6.703977 | X4119: 6.708531 | Y4119: 6.712298 | Z4119: 6.71555 | AA4119: 6.718503 | AB4119: 6.721329 | AC4119: 6.72416 | AD4119: 6.727096 | AE4119: 6.73021 | AF4119: 6.733553 | AG4119: 6.737158 | AH4119: 6.741043 | AI4119: 6.745213 | AJ4119: 6.749665 | AK4119: 6.754388 | AL4119: 6.759366 | AM4119: 6.764577 | AN4119: 6.769998 | AO4119: 6.781367 | AP4119: 6.775604
A4120: 46065 | B4120: 4.500247 | C4120: 4.837938 | D4120: 5.154667 | E4120: 5.424527 | F4120: 5.6535 | G4120: 5.8469 | H4120: 6.009441 | I4120: 6.145295 | J4120: 6.258154 | K4120: 6.351274 | L4120: 6.427525 | M4120: 6.489429 | N4120: 6.539202 | O4120: 6.57878 | P4120: 6.609854 | Q4120: 6.633899 | R4120: 6.652191 | S4120: 6.665836 | T4120: 6.675787 | U4120: 6.682862 | V4120: 6.687757 | W4120: 6.691067 | X4120: 6.69329 | Y4120: 6.694845 | Z4120: 6.69608 | AA4120: 6.69728 | AB4120: 6.698677 | AC4120: 6.700455 | AD4120: 6.702757 | AE4120: 6.705694 | AF4120: 6.709344 | AG4120: 6.713759 | AH4120: 6.718974 | AI4120: 6.725 | AJ4120: 6.731838 | AK4120: 6.739472 | AL4120: 6.747879 | AM4120: 6.757027 | AN4120: 6.766877 | AO4120: 6.788503 | AP4120: 6.777385
A4121: 46066 | B4121: 4.518279 | C4121: 4.853387 | D4121: 5.167578 | E4121: 5.435174 | F4121: 5.662145 | G4121: 5.85379 | H4121: 6.014808 | I4121: 6.149359 | J4121: 6.261118 | K4121: 6.353328 | L4121: 6.428845 | M4121: 6.490179 | N4121: 6.53953 | O4121: 6.578823 | P4121: 6.609737 | Q4121: 6.633734 | R4121: 6.652081 | S4121: 6.665873 | T4121: 6.676053 | U4121: 6.68343 | V4121: 6.688692 | W4121: 6.692424 | X4121: 6.695119 | Y4121: 6.697188 | Z4121: 6.698972 | AA4121: 6.700752 | AB4121: 6.702753 | AC4121: 6.705154 | AD4121: 6.708095 | AE4121: 6.71168 | AF4121: 6.715986 | AG4121: 6.721062 | AH4121: 6.726938 | AI4121: 6.733623 | AJ4121: 6.741116 | AK4121: 6.749398 | AL4121: 6.758445 | AM4121: 6.768223 | AN4121: 6.778692 | AO4121: 6.801517 | AP4121: 6.789806
A4122: 46071 | B4122: 4.566602 | C4122: 4.872319 | D4122: 5.163387 | E4122: 5.415273 | F4122: 5.632328 | G4122: 5.818495 | H4122: 5.977349 | I4122: 6.112123 | J4122: 6.225741 | K4122: 6.320841 | L4122: 6.399799 | M4122: 6.464754 | N4122: 6.517627 | O4122: 6.560139 | P4122: 6.593833 | Q4122: 6.620083 | R4122: 6.640114 | S4122: 6.655015 | T4122: 6.665749 | U4122: 6.673169 | V4122: 6.678022 | W4122: 6.680967 | X4122: 6.682575 | Y4122: 6.683344 | Z4122: 6.683704 | AA4122: 6.684022 | AB4122: 6.684613 | AC4122: 6.685738 | AD4122: 6.68762 | AE4122: 6.690436 | AF4122: 6.694334 | AG4122: 6.699427 | AH4122: 6.705802 | AI4122: 6.713522 | AJ4122: 6.722626 | AK4122: 6.733138 | AL4122: 6.745064 | AM4122: 6.758396 | AN4122: 6.773113 | AO4122: 6.806574 | AP4122: 6.789185
A4123: 46072 | B4123: 4.507835 | C4123: 4.823391 | D4123: 5.12324 | E4123: 5.382241 | F4123: 5.605059 | G4123: 5.795906 | H4123: 5.958579 | I4123: 6.096504 | J4123: 6.212761 | K4123: 6.310117 | L4123: 6.391056 | M4123: 6.457801 | N4123: 6.51234 | O4123: 6.556447 | P4123: 6.591702 | Q4123: 6.619506 | R4123: 6.641103 | S4123: 6.657592 | T4123: 6.669941 | U4123: 6.678999 | V4123: 6.685509 | W4123: 6.69012 | X4123: 6.693393 | Y4123: 6.695811 | Z4123: 6.69779 | AA4123: 6.699683 | AB4123: 6.701786 | AC4123: 6.704349 | AD4123: 6.707574 | AE4123: 6.711629 | AF4123: 6.716644 | AG4123: 6.72272 | AH4123: 6.729931 | AI4123: 6.738329 | AJ4123: 6.747945 | AK4123: 6.758792 | AL4123: 6.770869 | AM4123: 6.78416 | AN4123: 6.798642 | AO4123: 6.831028 | AP4123: 6.814278
A4124: 46073 | B4124: 4.493149 | C4124: 4.823888 | D4124: 5.135795 | E4124: 5.403086 | F4124: 5.631216 | G4124: 5.82506 | H4124: 5.98897 | I4124: 6.126828 | J4124: 6.242087 | K4124: 6.337817 | L4124: 6.416742 | M4124: 6.481275 | N4124: 6.533547 | O4124: 6.575437 | P4124: 6.608601 | Q4124: 6.63449 | R4124: 6.654374 | S4124: 6.669361 | T4124: 6.680414 | U4124: 6.688369 | V4124: 6.693943 | W4124: 6.697755 | X4124: 6.700332 | Y4124: 6.702118 | Z4124: 6.703491 | AA4124: 6.704764 | AB4124: 6.706194 | AC4124: 6.707992 | AD4124: 6.710326 | AE4124: 6.713327 | AF4124: 6.717094 | AG4124: 6.721701 | AH4124: 6.727194 | AI4124: 6.733603 | AJ4124: 6.740938 | AK4124: 6.749196 | AL4124: 6.758361 | AM4124: 6.768409 | AN4124: 6.779305 | AO4124: 6.803475 | AP4124: 6.791008
A4125: 46076 | B4125: 4.451798 | C4125: 4.790624 | D4125: 5.110211 | E4125: 5.384087 | F4125: 5.617792 | G4125: 5.816288 | H4125: 5.984012 | I4125: 6.124925 | J4125: 6.242561 | K4125: 6.340066 | L4125: 6.420236 | M4125: 6.485551 | N4125: 6.538207 | O4125: 6.580143 | P4125: 6.613071 | Q4125: 6.638492 | R4125: 6.657725 | S4125: 6.671922 | T4125: 6.682085 | U4125: 6.689084 | V4125: 6.693672 | W4125: 6.696494 | X4125: 6.698102 | Y4125: 6.698965 | Z4125: 6.69948 | AA4125: 6.699974 | AB4125: 6.700722 | AC4125: 6.701946 | AD4125: 6.703823 | AE4125: 6.706493 | AF4125: 6.710061 | AG4125: 6.714604 | AH4125: 6.720173 | AI4125: 6.726799 | AJ4125: 6.734492 | AK4125: 6.743249 | AL4125: 6.753053 | AM4125: 6.763875 | AN4125: 6.775678 | AO4125: 6.802049 | AP4125: 6.788419
A4126: 46077 | B4126: 4.453657 | C4126: 4.79144 | D4126: 5.111131 | E4126: 5.386004 | F4126: 5.621265 | G4126: 5.821609 | H4126: 5.991261 | I4126: 6.134025 | J4126: 6.253316 | K4126: 6.352196 | L4126: 6.433406 | M4126: 6.499398 | N4126: 6.552356 | O4126: 6.594229 | P4126: 6.626743 | Q4126: 6.651432 | R4126: 6.669649 | S4126: 6.682588 | T4126: 6.691297 | U4126: 6.696692 | V4126: 6.699575 | W4126: 6.700639 | X4126: 6.700484 | Y4126: 6.699623 | Z4126: 6.698497 | AA4126: 6.697474 | AB4126: 6.696867 | AC4126: 6.69693 | AD4126: 6.697875 | AE4126: 6.699868 | AF4126: 6.70304 | AG4126: 6.707488 | AH4126: 6.713283 | AI4126: 6.720468 | AJ4126: 6.729068 | AK4126: 6.739088 | AL4126: 6.750516 | AM4126: 6.763329 | AN4126: 6.777491 | AO4126: 6.809675 | AP4126: 6.792957
A4127: 46078 | B4127: 4.509248 | C4127: 4.830775 | D4127: 5.136449 | E4127: 5.400516 | F4127: 5.627611 | G4127: 5.821936 | H4127: 5.987298 | I4127: 6.127145 | J4127: 6.244589 | K4127: 6.34244 | L4127: 6.423231 | M4127: 6.489239 | N4127: 6.542508 | O4127: 6.584874 | P4127: 6.617975 | Q4127: 6.643276 | R4127: 6.662079 | S4127: 6.675543 | T4127: 6.684692 | U4127: 6.690431 | V4127: 6.693556 | W4127: 6.694763 | X4127: 6.694661 | Y4127: 6.693776 | Z4127: 6.692563 | AA4127: 6.691412 | AB4127: 6.690652 | AC4127: 6.690563 | AD4127: 6.691376 | AE4127: 6.693278 | AF4127: 6.696423 | AG4127: 6.700928 | AH4127: 6.706882 | AI4127: 6.71435 | AJ4127: 6.723372 | AK4127: 6.733968 | AL4127: 6.746141 | AM4127: 6.759881 | AN4127: 6.775164 | AO4127: 6.810203 | AP4127: 6.791952
A4128: 46080 | B4128: 4.55475 | C4128: 4.863317 | D4128: 5.157719 | E4128: 5.413031 | F4128: 5.633479 | G4128: 5.822907 | H4128: 5.984816 | I4128: 6.122383 | J4128: 6.238492 | K4128: 6.335753 | L4128: 6.416532 | M4128: 6.482964 | N4128: 6.536974 | O4128: 6.580296 | P4128: 6.614488 | Q4128: 6.640949 | R4128: 6.660927 | S4128: 6.67554 | T4128: 6.68578 | U4128: 6.69253 | V4128: 6.696569 | W4128: 6.698586 | X4128: 6.699185 | Y4128: 6.698891 | Z4128: 6.698165 | AA4128: 6.697402 | AB4128: 6.696942 | AC4128: 6.697074 | AD4128: 6.69804 | AE4128: 6.700042 | AF4128: 6.703247 | AG4128: 6.707786 | AH4128: 6.713762 | AI4128: 6.721253 | AJ4128: 6.730312 | AK4128: 6.740973 | AL4128: 6.753251 | AM4128: 6.767147 | AN4128: 6.782647 | AO4128: 6.818348 | AP4128: 6.799726
... A4130: 46083 | B4130: 4.585991 | C4130: 4.884124 | D4130: 5.169615 | E4130: 5.418133 | F4130: 5.633507 | G4130: 5.819243 | H4130: 5.978549 | I4130: 6.114356 | J4130: 6.229341 | K4130: 6.325946 | L4130: 6.406391 | M4130: 6.472698 | N4130: 6.5267 | O4130: 6.570062 | P4130: 6.604287 | Q4130: 6.630735 | R4130: 6.65063 | S4130: 6.665075 | T4130: 6.675057 | U4130: 6.681462 | V4130: 6.685078 | W4130: 6.686606 | X4130: 6.68667 | Y4130: 6.685816 | Z4130: 6.684527 | AA4130: 6.683224 | AB4130: 6.682273 | AC4130: 6.681989 | AD4130: 6.68264 | AE4130: 6.684456 | AF4130: 6.687627 | AG4130: 6.692308 | AH4130: 6.698627 | AI4130: 6.706683 | AJ4130: 6.716548 | AK4130: 6.728276 | AL4130: 6.741898 | AM4130: 6.757431 | AN4130: 6.774874 | AO4130: 6.815423 | AP4130: 6.794213
B4131: 4.647435 | C4131: 4.935042 | D4131: 5.2115 | E4131: 5.453044 | F4131: 5.663077 | G4131: 5.844741 | H4131: 6.000938 | I4131: 6.134344 | J4131: 6.247423 | K4131: 6.342442 | L4131: 6.421487 | M4131: 6.486471 | N4131: 6.539147 | O4131: 6.581122 | P4131: 6.613863 | Q4131: 6.63871 | R4131: 6.656882 | S4131: 6.669489 | T4131: 6.677537 | U4131: 6.681937 | V4131: 6.683512 | W4131: 6.683002 | X4131: 6.681072 | Y4131: 6.678317 | Z4131: 6.675267 | AA4131: 6.672393 | AB4131: 6.67011 | AC4131: 6.668784 | AD4131: 6.668733 | AE4131: 6.670233 | AF4131: 6.673519 | AG4131: 6.678793 | AH4131: 6.686222 | AI4131: 6.695945 | AJ4131: 6.708072 | AK4131: 6.722689 | AL4131: 6.739858 | AM4131: 6.759624 | AN4131: 6.78201 | AO4131: 6.834662 | AP4131: 6.807025

Sheet dbtrain
A1: tanggal_lelang_pricing | B1: code | C1: tenor | D1: ust_10y | E1: ust_2y | F1: vix | G1: move | H1: dxy | I1: ndf_1m | J1: ndf_12m | K1: idr_regn | L1: ust_3m | M1: xau_gold | N1: inflation | O1: slope_10y_2y | P1: slope_2y_3m | Q1: cds_5y | R1: indo_10y | S1: tenor_x_ust10y | T1: vix_x_move | U1: prev_way_awarded_code | V1: days_since_prev_auction_code | W1: auctions_since_prev_code | X1: prev_bid_to_cover_ratio_code | Y1: prev_total_penawaran_code | Z1: prev_total_penawaran_diterima_code | AA1: prev_owners_estimate_code | AB1: owners_estimate
A2: 43837 | B2: bm05 | C2: 5.431896 | D2: =INDEX(dbbbg,MATCH($A2,db00!$A$3:$A$1611,0),2) -> 1.81 | E2: =INDEX(dbbbg,MATCH($A2,db00!$A$3:$A$1611,0),3) -> 1.546 | F2: =INDEX(dbbbg,MATCH($A2,db00!$A$3:$A$1611,0),4) -> 13.85 | G2: =INDEX(dbbbg,MATCH($A2,db00!$A$3:$A$1611,0),5) -> 62.79 | H2: =INDEX(dbbbg,MATCH($A2,db00!$A$3:$A$1611,0),6) -> 96.671 | I2: =INDEX(dbbbg,MATCH($A2,db00!$A$3:$A$1611,0),13) -> 0.15060241 | J2: =INDEX(dbbbg,MATCH($A2,db00!$A$3:$A$1611,0),14) -> 3.9515204 | K2: =INDEX(dbbbg,MATCH($A2,db00!$A$3:$A$1611,0),9) -> 13944 | L2: =INDEX(dbbbg,MATCH($A2,db00!$A$3:$A$1611,0),10) -> 1.528 | M2: =INDEX(dbbbg,MATCH($A2,db00!$A$3:$A$1611,0),11) -> 1565.74 | N2: =INDEX(dbbbg,MATCH($A2,db00!$A$3:$A$1611,0),12) -> 2.72 | O2: =D2-E2 -> 0.264 | P2: =E2-L2 -> 0.018 | Q2: =INDEX(cds,MATCH($A2,cds!$I$3:$I$4708,0),5) -> 65.29 | R2: =INDEX(idyield,MATCH($A2,yieldid!$A$3:$A$4130,0),12) -> 7.217194 | S2: =C2*D2 -> 9.8317317 | T2: =F2*G2 -> 869.6415 | W2: 0 | AB2: 6.39
A3: 43837 | B3: bm10 | C3: 10.683094 | D3: =INDEX(dbbbg,MATCH($A3,db00!$A$3:$A$1611,0),2) -> 1.81 | E3: =INDEX(dbbbg,MATCH($A3,db00!$A$3:$A$1611,0),3) -> 1.546 | F3: =INDEX(dbbbg,MATCH($A3,db00!$A$3:$A$1611,0),4) -> 13.85 | G3: =INDEX(dbbbg,MATCH($A3,db00!$A$3:$A$1611,0),5) -> 62.79 | H3: =INDEX(dbbbg,MATCH($A3,db00!$A$3:$A$1611,0),6) -> 96.671 | I3: =INDEX(dbbbg,MATCH($A3,db00!$A$3:$A$1611,0),13) -> 0.15060241 | J3: =INDEX(dbbbg,MATCH($A3,db00!$A$3:$A$1611,0),14) -> 3.9515204 | K3: =INDEX(dbbbg,MATCH($A3,db00!$A$3:$A$1611,0),9) -> 13944 | L3: =INDEX(dbbbg,MATCH($A3,db00!$A$3:$A$1611,0),10) -> 1.528 | M3: =INDEX(dbbbg,MATCH($A3,db00!$A$3:$A$1611,0),11) -> 1565.74 | N3: =INDEX(dbbbg,MATCH($A3,db00!$A$3:$A$1611,0),12) -> 2.72 | O3: =D3-E3 -> 0.264 | P3: =E3-L3 -> 0.018 | Q3: =INDEX(cds,MATCH($A3,cds!$I$3:$I$4708,0),5) -> 65.29 | R3: =INDEX(idyield,MATCH($A3,yieldid!$A$3:$A$4130,0),12) -> 7.217194 | S3: =C3*D3 -> 19.3364 | T3: =F3*G3 -> 869.6415 | W3: 0 | AB3: 7.1
A4: 43837 | B4: bm15 | C4: 15.430527 | D4: =INDEX(dbbbg,MATCH($A4,db00!$A$3:$A$1611,0),2) -> 1.81 | E4: =INDEX(dbbbg,MATCH($A4,db00!$A$3:$A$1611,0),3) -> 1.546 | F4: =INDEX(dbbbg,MATCH($A4,db00!$A$3:$A$1611,0),4) -> 13.85 | G4: =INDEX(dbbbg,MATCH($A4,db00!$A$3:$A$1611,0),5) -> 62.79 | H4: =INDEX(dbbbg,MATCH($A4,db00!$A$3:$A$1611,0),6) -> 96.671 | I4: =INDEX(dbbbg,MATCH($A4,db00!$A$3:$A$1611,0),13) -> 0.15060241 | J4: =INDEX(dbbbg,MATCH($A4,db00!$A$3:$A$1611,0),14) -> 3.9515204 | K4: =INDEX(dbbbg,MATCH($A4,db00!$A$3:$A$1611,0),9) -> 13944 | L4: =INDEX(dbbbg,MATCH($A4,db00!$A$3:$A$1611,0),10) -> 1.528 | M4: =INDEX(dbbbg,MATCH($A4,db00!$A$3:$A$1611,0),11) -> 1565.74 | N4: =INDEX(dbbbg,MATCH($A4,db00!$A$3:$A$1611,0),12) -> 2.72 | O4: =D4-E4 -> 0.264 | P4: =E4-L4 -> 0.018 | Q4: =INDEX(cds,MATCH($A4,cds!$I$3:$I$4708,0),5) -> 65.29 | R4: =INDEX(idyield,MATCH($A4,yieldid!$A$3:$A$4130,0),12) -> 7.217194 | S4: =C4*D4 -> 27.929254 | T4: =F4*G4 -> 869.6415 | W4: 0 | AB4: 7.45
A5: 43837 | B5: bm20 | C5: 20.265572 | D5: =INDEX(dbbbg,MATCH($A5,db00!$A$3:$A$1611,0),2) -> 1.81 | E5: =INDEX(dbbbg,MATCH($A5,db00!$A$3:$A$1611,0),3) -> 1.546 | F5: =INDEX(dbbbg,MATCH($A5,db00!$A$3:$A$1611,0),4) -> 13.85 | G5: =INDEX(dbbbg,MATCH($A5,db00!$A$3:$A$1611,0),5) -> 62.79 | H5: =INDEX(dbbbg,MATCH($A5,db00!$A$3:$A$1611,0),6) -> 96.671 | I5: =INDEX(dbbbg,MATCH($A5,db00!$A$3:$A$1611,0),13) -> 0.15060241 | J5: =INDEX(dbbbg,MATCH($A5,db00!$A$3:$A$1611,0),14) -> 3.9515204 | K5: =INDEX(dbbbg,MATCH($A5,db00!$A$3:$A$1611,0),9) -> 13944 | L5: =INDEX(dbbbg,MATCH($A5,db00!$A$3:$A$1611,0),10) -> 1.528 | M5: =INDEX(dbbbg,MATCH($A5,db00!$A$3:$A$1611,0),11) -> 1565.74 | N5: =INDEX(dbbbg,MATCH($A5,db00!$A$3:$A$1611,0),12) -> 2.72 | O5: =D5-E5 -> 0.264 | P5: =E5-L5 -> 0.018 | Q5: =INDEX(cds,MATCH($A5,cds!$I$3:$I$4708,0),5) -> 65.29 | R5: =INDEX(idyield,MATCH($A5,yieldid!$A$3:$A$4130,0),12) -> 7.217194 | S5: =C5*D5 -> 36.680684 | T5: =F5*G5 -> 869.6415 | W5: 0 | AB5: 7.54
A6: 43837 | B6: bm30 | C6: 28.347707 | D6: =INDEX(dbbbg,MATCH($A6,db00!$A$3:$A$1611,0),2) -> 1.81 | E6: =INDEX(dbbbg,MATCH($A6,db00!$A$3:$A$1611,0),3) -> 1.546 | F6: =INDEX(dbbbg,MATCH($A6,db00!$A$3:$A$1611,0),4) -> 13.85 | G6: =INDEX(dbbbg,MATCH($A6,db00!$A$3:$A$1611,0),5) -> 62.79 | H6: =INDEX(dbbbg,MATCH($A6,db00!$A$3:$A$1611,0),6) -> 96.671 | I6: =INDEX(dbbbg,MATCH($A6,db00!$A$3:$A$1611,0),13) -> 0.15060241 | J6: =INDEX(dbbbg,MATCH($A6,db00!$A$3:$A$1611,0),14) -> 3.9515204 | K6: =INDEX(dbbbg,MATCH($A6,db00!$A$3:$A$1611,0),9) -> 13944 | L6: =INDEX(dbbbg,MATCH($A6,db00!$A$3:$A$1611,0),10) -> 1.528 | M6: =INDEX(dbbbg,MATCH($A6,db00!$A$3:$A$1611,0),11) -> 1565.74 | N6: =INDEX(dbbbg,MATCH($A6,db00!$A$3:$A$1611,0),12) -> 2.72 | O6: =D6-E6 -> 0.264 | P6: =E6-L6 -> 0.018 | Q6: =INDEX(cds,MATCH($A6,cds!$I$3:$I$4708,0),5) -> 65.29 | R6: =INDEX(idyield,MATCH($A6,yieldid!$A$3:$A$4130,0),12) -> 7.217194 | S6: =C6*D6 -> 51.30935 | T6: =F6*G6 -> 869.6415 | W6: 0 | AB6: 7.72
A7: 43837 | B7: spn03m | C7: 0.25188227 | D7: =INDEX(dbbbg,MATCH($A7,db00!$A$3:$A$1611,0),2) -> 1.81 | E7: =INDEX(dbbbg,MATCH($A7,db00!$A$3:$A$1611,0),3) -> 1.546 | F7: =INDEX(dbbbg,MATCH($A7,db00!$A$3:$A$1611,0),4) -> 13.85 | G7: =INDEX(dbbbg,MATCH($A7,db00!$A$3:$A$1611,0),5) -> 62.79 | H7: =INDEX(dbbbg,MATCH($A7,db00!$A$3:$A$1611,0),6) -> 96.671 | I7: =INDEX(dbbbg,MATCH($A7,db00!$A$3:$A$1611,0),13) -> 0.15060241 | J7: =INDEX(dbbbg,MATCH($A7,db00!$A$3:$A$1611,0),14) -> 3.9515204 | K7: =INDEX(dbbbg,MATCH($A7,db00!$A$3:$A$1611,0),9) -> 13944 | L7: =INDEX(dbbbg,MATCH($A7,db00!$A$3:$A$1611,0),10) -> 1.528 | M7: =INDEX(dbbbg,MATCH($A7,db00!$A$3:$A$1611,0),11) -> 1565.74 | N7: =INDEX(dbbbg,MATCH($A7,db00!$A$3:$A$1611,0),12) -> 2.72 | O7: =D7-E7 -> 0.264 | P7: =E7-L7 -> 0.018 | Q7: =INDEX(cds,MATCH($A7,cds!$I$3:$I$4708,0),5) -> 65.29 | R7: =INDEX(idyield,MATCH($A7,yieldid!$A$3:$A$4130,0),12) -> 7.217194 | S7: =C7*D7 -> 0.45590691 | T7: =F7*G7 -> 869.6415 | W7: 0 | AB7: 4.65
A8: 43837 | B8: spn12m | C8: 0.99931554 | D8: =INDEX(dbbbg,MATCH($A8,db00!$A$3:$A$1611,0),2) -> 1.81 | E8: =INDEX(dbbbg,MATCH($A8,db00!$A$3:$A$1611,0),3) -> 1.546 | F8: =INDEX(dbbbg,MATCH($A8,db00!$A$3:$A$1611,0),4) -> 13.85 | G8: =INDEX(dbbbg,MATCH($A8,db00!$A$3:$A$1611,0),5) -> 62.79 | H8: =INDEX(dbbbg,MATCH($A8,db00!$A$3:$A$1611,0),6) -> 96.671 | I8: =INDEX(dbbbg,MATCH($A8,db00!$A$3:$A$1611,0),13) -> 0.15060241 | J8: =INDEX(dbbbg,MATCH($A8,db00!$A$3:$A$1611,0),14) -> 3.9515204 | K8: =INDEX(dbbbg,MATCH($A8,db00!$A$3:$A$1611,0),9) -> 13944 | L8: =INDEX(dbbbg,MATCH($A8,db00!$A$3:$A$1611,0),10) -> 1.528 | M8: =INDEX(dbbbg,MATCH($A8,db00!$A$3:$A$1611,0),11) -> 1565.74 | N8: =INDEX(dbbbg,MATCH($A8,db00!$A$3:$A$1611,0),12) -> 2.72 | O8: =D8-E8 -> 0.264 | P8: =E8-L8 -> 0.018 | Q8: =INDEX(cds,MATCH($A8,cds!$I$3:$I$4708,0),5) -> 65.29 | R8: =INDEX(idyield,MATCH($A8,yieldid!$A$3:$A$4130,0),12) -> 7.217194 | S8: =C8*D8 -> 1.8087611 | T8: =F8*G8 -> 869.6415 | W8: 0 | AB8: 4.9
A9: 43851 | B9: bm05 | C9: 5.3935661 | D9: =INDEX(dbbbg,MATCH($A9,db00!$A$3:$A$1611,0),2) -> 1.822 | E9: =INDEX(dbbbg,MATCH($A9,db00!$A$3:$A$1611,0),3) -> 1.56 | F9: =INDEX(dbbbg,MATCH($A9,db00!$A$3:$A$1611,0),4) -> 12.1 | G9: =INDEX(dbbbg,MATCH($A9,db00!$A$3:$A$1611,0),5) -> 49.67 | H9: =INDEX(dbbbg,MATCH($A9,db00!$A$3:$A$1611,0),6) -> 97.606 | I9: =INDEX(dbbbg,MATCH($A9,db00!$A$3:$A$1611,0),13) -> 0.14663832 | J9: =INDEX(dbbbg,MATCH($A9,db00!$A$3:$A$1611,0),14) -> 3.5266515 | K9: =INDEX(dbbbg,MATCH($A9,db00!$A$3:$A$1611,0),9) -> 13639 | L9: =INDEX(dbbbg,MATCH($A9,db00!$A$3:$A$1611,0),10) -> 1.556 | M9: =INDEX(dbbbg,MATCH($A9,db00!$A$3:$A$1611,0),11) -> 1560.77 | N9: =INDEX(dbbbg,MATCH($A9,db00!$A$3:$A$1611,0),12) -> 2.72 | O9: =D9-E9 -> 0.262 | P9: =E9-L9 -> 0.004 | Q9: =INDEX(cds,MATCH($A9,cds!$I$3:$I$4708,0),5) -> 59.975 | R9: =INDEX(idyield,MATCH($A9,yieldid!$A$3:$A$4130,0),12) -> 7.057688 | S9: =C9*D9 -> 9.8270773 | T9: =F9*G9 -> 601.007 | U9: 6.37939 | V9: 14 | W9: 1 | X9: 3.0149381 | Y9: 17034400 | Z9: 5650000 | AA9: 6.39 | AB9: 6.07
A10: 43851 | B10: bm10 | C10: 10.644764 | D10: =INDEX(dbbbg,MATCH($A10,db00!$A$3:$A$1611,0),2) -> 1.822 | E10: =INDEX(dbbbg,MATCH($A10,db00!$A$3:$A$1611,0),3) -> 1.56 | F10: =INDEX(dbbbg,MATCH($A10,db00!$A$3:$A$1611,0),4) -> 12.1 | G10: =INDEX(dbbbg,MATCH($A10,db00!$A$3:$A$1611,0),5) -> 49.67 | H10: =INDEX(dbbbg,MATCH($A10,db00!$A$3:$A$1611,0),6) -> 97.606 | I10: =INDEX(dbbbg,MATCH($A10,db00!$A$3:$A$1611,0),13) -> 0.14663832 | J10: =INDEX(dbbbg,MATCH($A10,db00!$A$3:$A$1611,0),14) -> 3.5266515 | K10: =INDEX(dbbbg,MATCH($A10,db00!$A$3:$A$1611,0),9) -> 13639 | L10: =INDEX(dbbbg,MATCH($A10,db00!$A$3:$A$1611,0),10) -> 1.556 | M10: =INDEX(dbbbg,MATCH($A10,db00!$A$3:$A$1611,0),11) -> 1560.77 | N10: =INDEX(dbbbg,MATCH($A10,db00!$A$3:$A$1611,0),12) -> 2.72 | O10: =D10-E10 -> 0.262 | P10: =E10-L10 -> 0.004 | Q10: =INDEX(cds,MATCH($A10,cds!$I$3:$I$4708,0),5) -> 59.975 | R10: =INDEX(idyield,MATCH($A10,yieldid!$A$3:$A$4130,0),12) -> 7.057688 | S10: =C10*D10 -> 19.39476 | T10: =F10*G10 -> 601.007 | U10: 7.09341 | V10: 14 | W10: 1 | X10: 4.4977344 | Y10: 28785500 | Z10: 6400000 | AA10: 7.1 | AB10: 6.81
A11: 43851 | B11: bm15 | C11: 15.392197 | D11: =INDEX(dbbbg,MATCH($A11,db00!$A$3:$A$1611,0),2) -> 1.822 | E11: =INDEX(dbbbg,MATCH($A11,db00!$A$3:$A$1611,0),3) -> 1.56 | F11: =INDEX(dbbbg,MATCH($A11,db00!$A$3:$A$1611,0),4) -> 12.1 | G11: =INDEX(dbbbg,MATCH($A11,db00!$A$3:$A$1611,0),5) -> 49.67 | H11: =INDEX(dbbbg,MATCH($A11,db00!$A$3:$A$1611,0),6) -> 97.606 | I11: =INDEX(dbbbg,MATCH($A11,db00!$A$3:$A$1611,0),13) -> 0.14663832 | J11: =INDEX(dbbbg,MATCH($A11,db00!$A$3:$A$1611,0),14) -> 3.5266515 | K11: =INDEX(dbbbg,MATCH($A11,db00!$A$3:$A$1611,0),9) -> 13639 | L11: =INDEX(dbbbg,MATCH($A11,db00!$A$3:$A$1611,0),10) -> 1.556 | M11: =INDEX(dbbbg,MATCH($A11,db00!$A$3:$A$1611,0),11) -> 1560.77 | N11: =INDEX(dbbbg,MATCH($A11,db00!$A$3:$A$1611,0),12) -> 2.72 | O11: =D11-E11 -> 0.262 | P11: =E11-L11 -> 0.004 | Q11: =INDEX(cds,MATCH($A11,cds!$I$3:$I$4708,0),5) -> 59.975 | R11: =INDEX(idyield,MATCH($A11,yieldid!$A$3:$A$4130,0),12) -> 7.057688 | S11: =C11*D11 -> 28.044583 | T11: =F11*G11 -> 601.007 | U11: 7.44384 | V11: 14 | W11: 1 | X11: 1.9516129 | Y11: 6050000 | Z11: 3100000 | AA11: 7.45 | AB11: 7.31
A12: 43851 | B12: bm20 | C12: 20.227242 | D12: =INDEX(dbbbg,MATCH($A12,db00!$A$3:$A$1611,0),2) -> 1.822 | E12: =INDEX(dbbbg,MATCH($A12,db00!$A$3:$A$1611,0),3) -> 1.56 | F12: =INDEX(dbbbg,MATCH($A12,db00!$A$3:$A$1611,0),4) -> 12.1 | G12: =INDEX(dbbbg,MATCH($A12,db00!$A$3:$A$1611,0),5) -> 49.67 | H12: =INDEX(dbbbg,MATCH($A12,db00!$A$3:$A$1611,0),6) -> 97.606 | I12: =INDEX(dbbbg,MATCH($A12,db00!$A$3:$A$1611,0),13) -> 0.14663832 | J12: =INDEX(dbbbg,MATCH($A12,db00!$A$3:$A$1611,0),14) -> 3.5266515 | K12: =INDEX(dbbbg,MATCH($A12,db00!$A$3:$A$1611,0),9) -> 13639 | L12: =INDEX(dbbbg,MATCH($A12,db00!$A$3:$A$1611,0),10) -> 1.556 | M12: =INDEX(dbbbg,MATCH($A12,db00!$A$3:$A$1611,0),11) -> 1560.77 | N12: =INDEX(dbbbg,MATCH($A12,db00!$A$3:$A$1611,0),12) -> 2.72 | O12: =D12-E12 -> 0.262 | P12: =E12-L12 -> 0.004 | Q12: =INDEX(cds,MATCH($A12,cds!$I$3:$I$4708,0),5) -> 59.975 | R12: =INDEX(idyield,MATCH($A12,yieldid!$A$3:$A$4130,0),12) -> 7.057688 | S12: =C12*D12 -> 36.854034 | T12: =F12*G12 -> 601.007 | U12: 7.53888 | V12: 14 | W12: 1 | X12: 3.2166667 | Y12: 2412500 | Z12: 750000 | AA12: 7.54 | AB12: 7.4
A13: 43851 | B13: bm30 | C13: 28.309377 | D13: =INDEX(dbbbg,MATCH($A13,db00!$A$3:$A$1611,0),2) -> 1.822 | E13: =INDEX(dbbbg,MATCH($A13,db00!$A$3:$A$1611,0),3) -> 1.56 | F13: =INDEX(dbbbg,MATCH($A13,db00!$A$3:$A$1611,0),4) -> 12.1 | G13: =INDEX(dbbbg,MATCH($A13,db00!$A$3:$A$1611,0),5) -> 49.67 | H13: =INDEX(dbbbg,MATCH($A13,db00!$A$3:$A$1611,0),6) -> 97.606 | I13: =INDEX(dbbbg,MATCH($A13,db00!$A$3:$A$1611,0),13) -> 0.14663832 | J13: =INDEX(dbbbg,MATCH($A13,db00!$A$3:$A$1611,0),14) -> 3.5266515 | K13: =INDEX(dbbbg,MATCH($A13,db00!$A$3:$A$1611,0),9) -> 13639 | L13: =INDEX(dbbbg,MATCH($A13,db00!$A$3:$A$1611,0),10) -> 1.556 | M13: =INDEX(dbbbg,MATCH($A13,db00!$A$3:$A$1611,0),11) -> 1560.77 | N13: =INDEX(dbbbg,MATCH($A13,db00!$A$3:$A$1611,0),12) -> 2.72 | O13: =D13-E13 -> 0.262 | P13: =E13-L13 -> 0.004 | Q13: =INDEX(cds,MATCH($A13,cds!$I$3:$I$4708,0),5) -> 59.975 | R13: =INDEX(idyield,MATCH($A13,yieldid!$A$3:$A$4130,0),12) -> 7.057688 | S13: =C13*D13 -> 51.579685 | T13: =F13*G13 -> 601.007 | U13: 7.71894 | V13: 14 | W13: 1 | X13: 1.4725455 | Y13: 1619800 | Z13: 1100000 | AA13: 7.72 | AB13: 7.6
A14: 43851 | B14: spn03m | C14: 0.24640657 | D14: =INDEX(dbbbg,MATCH($A14,db00!$A$3:$A$1611,0),2) -> 1.822 | E14: =INDEX(dbbbg,MATCH($A14,db00!$A$3:$A$1611,0),3) -> 1.56 | F14: =INDEX(dbbbg,MATCH($A14,db00!$A$3:$A$1611,0),4) -> 12.1 | G14: =INDEX(dbbbg,MATCH($A14,db00!$A$3:$A$1611,0),5) -> 49.67 | H14: =INDEX(dbbbg,MATCH($A14,db00!$A$3:$A$1611,0),6) -> 97.606 | I14: =INDEX(dbbbg,MATCH($A14,db00!$A$3:$A$1611,0),13) -> 0.14663832 | J14: =INDEX(dbbbg,MATCH($A14,db00!$A$3:$A$1611,0),14) -> 3.5266515 | K14: =INDEX(dbbbg,MATCH($A14,db00!$A$3:$A$1611,0),9) -> 13639 | L14: =INDEX(dbbbg,MATCH($A14,db00!$A$3:$A$1611,0),10) -> 1.556 | M14: =INDEX(dbbbg,MATCH($A14,db00!$A$3:$A$1611,0),11) -> 1560.77 | N14: =INDEX(dbbbg,MATCH($A14,db00!$A$3:$A$1611,0),12) -> 2.72 | O14: =D14-E14 -> 0.262 | P14: =E14-L14 -> 0.004 | Q14: =INDEX(cds,MATCH($A14,cds!$I$3:$I$4708,0),5) -> 59.975 | R14: =INDEX(idyield,MATCH($A14,yieldid!$A$3:$A$4130,0),12) -> 7.057688 | S14: =C14*D14 -> 0.44895277 | T14: =F14*G14 -> 601.007 | U14: 4.41733 | V14: 14 | W14: 1 | X14: 8.8 | Y14: 13200000 | Z14: 1500000 | AA14: 4.65 | AB14: 4.4
A15: 43851 | B15: spn12m | C15: 0.96098563 | D15: =INDEX(dbbbg,MATCH($A15,db00!$A$3:$A$1611,0),2) -> 1.822 | E15: =INDEX(dbbbg,MATCH($A15,db00!$A$3:$A$1611,0),3) -> 1.56 | F15: =INDEX(dbbbg,MATCH($A15,db00!$A$3:$A$1611,0),4) -> 12.1 | G15: =INDEX(dbbbg,MATCH($A15,db00!$A$3:$A$1611,0),5) -> 49.67 | H15: =INDEX(dbbbg,MATCH($A15,db00!$A$3:$A$1611,0),6) -> 97.606 | I15: =INDEX(dbbbg,MATCH($A15,db00!$A$3:$A$1611,0),13) -> 0.14663832 | J15: =INDEX(dbbbg,MATCH($A15,db00!$A$3:$A$1611,0),14) -> 3.5266515 | K15: =INDEX(dbbbg,MATCH($A15,db00!$A$3:$A$1611,0),9) -> 13639 | L15: =INDEX(dbbbg,MATCH($A15,db00!$A$3:$A$1611,0),10) -> 1.556 | M15: =INDEX(dbbbg,MATCH($A15,db00!$A$3:$A$1611,0),11) -> 1560.77 | N15: =INDEX(dbbbg,MATCH($A15,db00!$A$3:$A$1611,0),12) -> 2.72 | O15: =D15-E15 -> 0.262 | P15: =E15-L15 -> 0.004 | Q15: =INDEX(cds,MATCH($A15,cds!$I$3:$I$4708,0),5) -> 59.975 | R15: =INDEX(idyield,MATCH($A15,yieldid!$A$3:$A$4130,0),12) -> 7.057688 | S15: =C15*D15 -> 1.7509158 | T15: =F15*G15 -> 601.007 | U15: 4.64067 | V15: 14 | W15: 1 | X15: 8.2933333 | Y15: 12440000 | Z15: 1500000 | AA15: 4.9 | AB15: 4.6
A16: 43865 | B16: bm05 | C16: 5.3552361 | D16: =INDEX(dbbbg,MATCH($A16,db00!$A$3:$A$1611,0),2) -> 1.528 | E16: =INDEX(dbbbg,MATCH($A16,db00!$A$3:$A$1611,0),3) -> 1.355 | F16: =INDEX(dbbbg,MATCH($A16,db00!$A$3:$A$1611,0),4) -> 17.97 | G16: =INDEX(dbbbg,MATCH($A16,db00!$A$3:$A$1611,0),5) -> 72.81 | H16: =INDEX(dbbbg,MATCH($A16,db00!$A$3:$A$1611,0),6) -> 97.8 | I16: =INDEX(dbbbg,MATCH($A16,db00!$A$3:$A$1611,0),13) -> 0.32746325 | J16: =INDEX(dbbbg,MATCH($A16,db00!$A$3:$A$1611,0),14) -> 4.1915296 | K16: =INDEX(dbbbg,MATCH($A16,db00!$A$3:$A$1611,0),9) -> 13742 | L16: =INDEX(dbbbg,MATCH($A16,db00!$A$3:$A$1611,0),10) -> 1.562 | M16: =INDEX(dbbbg,MATCH($A16,db00!$A$3:$A$1611,0),11) -> 1576.73 | N16: =INDEX(dbbbg,MATCH($A16,db00!$A$3:$A$1611,0),12) -> 2.68 | O16: =D16-E16 -> 0.173 | P16: =E16-L16 -> -0.207 | Q16: =INDEX(cds,MATCH($A16,cds!$I$3:$I$4708,0),5) -> 65.615 | R16: =INDEX(idyield,MATCH($A16,yieldid!$A$3:$A$4130,0),12) -> 6.949604 | S16: =C16*D16 -> 8.1828008 | T16: =F16*G16 -> 1308.3957 | U16: 6.03855 | V16: 14 | W16: 2 | X16: 2.999964 | Y16: 16649800 | Z16: 5550000 | AA16: 6.07 | AB16: 6.01
A17: 43865 | B17: bm10 | C17: 10.606434 | D17: =INDEX(dbbbg,MATCH($A17,db00!$A$3:$A$1611,0),2) -> 1.528 | E17: =INDEX(dbbbg,MATCH($A17,db00!$A$3:$A$1611,0),3) -> 1.355 | F17: =INDEX(dbbbg,MATCH($A17,db00!$A$3:$A$1611,0),4) -> 17.97 | G17: =INDEX(dbbbg,MATCH($A17,db00!$A$3:$A$1611,0),5) -> 72.81 | H17: =INDEX(dbbbg,MATCH($A17,db00!$A$3:$A$1611,0),6) -> 97.8 | I17: =INDEX(dbbbg,MATCH($A17,db00!$A$3:$A$1611,0),13) -> 0.32746325 | J17: =INDEX(dbbbg,MATCH($A17,db00!$A$3:$A$1611,0),14) -> 4.1915296 | K17: =INDEX(dbbbg,MATCH($A17,db00!$A$3:$A$1611,0),9) -> 13742 | L17: =INDEX(dbbbg,MATCH($A17,db00!$A$3:$A$1611,0),10) -> 1.562 | M17: =INDEX(dbbbg,MATCH($A17,db00!$A$3:$A$1611,0),11) -> 1576.73 | N17: =INDEX(dbbbg,MATCH($A17,db00!$A$3:$A$1611,0),12) -> 2.68 | O17: =D17-E17 -> 0.173 | P17: =E17-L17 -> -0.207 | Q17: =INDEX(cds,MATCH($A17,cds!$I$3:$I$4708,0),5) -> 65.615 | R17: =INDEX(idyield,MATCH($A17,yieldid!$A$3:$A$4130,0),12) -> 6.949604 | S17: =C17*D17 -> 16.206631 | T17: =F17*G17 -> 1308.3957 | U17: 6.78497 | V17: 14 | W17: 2 | X17: 4.1007143 | Y17: 17223000 | Z17: 4200000 | AA17: 6.81 | AB17: 6.65
A18: 43865 | B18: bm15 | C18: 15.353867 | D18: =INDEX(dbbbg,MATCH($A18,db00!$A$3:$A$1611,0),2) -> 1.528 | E18: =INDEX(dbbbg,MATCH($A18,db00!$A$3:$A$1611,0),3) -> 1.355 | F18: =INDEX(dbbbg,MATCH($A18,db00!$A$3:$A$1611,0),4) -> 17.97 | G18: =INDEX(dbbbg,MATCH($A18,db00!$A$3:$A$1611,0),5) -> 72.81 | H18: =INDEX(dbbbg,MATCH($A18,db00!$A$3:$A$1611,0),6) -> 97.8 | I18: =INDEX(dbbbg,MATCH($A18,db00!$A$3:$A$1611,0),13) -> 0.32746325 | J18: =INDEX(dbbbg,MATCH($A18,db00!$A$3:$A$1611,0),14) -> 4.1915296 | K18: =INDEX(dbbbg,MATCH($A18,db00!$A$3:$A$1611,0),9) -> 13742 | L18: =INDEX(dbbbg,MATCH($A18,db00!$A$3:$A$1611,0),10) -> 1.562 | M18: =INDEX(dbbbg,MATCH($A18,db00!$A$3:$A$1611,0),11) -> 1576.73 | N18: =INDEX(dbbbg,MATCH($A18,db00!$A$3:$A$1611,0),12) -> 2.68 | O18: =D18-E18 -> 0.173 | P18: =E18-L18 -> -0.207 | Q18: =INDEX(cds,MATCH($A18,cds!$I$3:$I$4708,0),5) -> 65.615 | R18: =INDEX(idyield,MATCH($A18,yieldid!$A$3:$A$4130,0),12) -> 6.949604 | S18: =C18*D18 -> 23.460709 | T18: =F18*G18 -> 1308.3957 | U18: 7.30625 | V18: 14 | W18: 2 | X18: 2.4577273 | Y18: 5407000 | Z18: 2200000 | AA18: 7.31 | AB18: 7.17
A19: 43865 | B19: bm20 | C19: 20.188912 | D19: =INDEX(dbbbg,MATCH($A19,db00!$A$3:$A$1611,0),2) -> 1.528 | E19: =INDEX(dbbbg,MATCH($A19,db00!$A$3:$A$1611,0),3) -> 1.355 | F19: =INDEX(dbbbg,MATCH($A19,db00!$A$3:$A$1611,0),4) -> 17.97 | G19: =INDEX(dbbbg,MATCH($A19,db00!$A$3:$A$1611,0),5) -> 72.81 | H19: =INDEX(dbbbg,MATCH($A19,db00!$A$3:$A$1611,0),6) -> 97.8 | I19: =INDEX(dbbbg,MATCH($A19,db00!$A$3:$A$1611,0),13) -> 0.32746325 | J19: =INDEX(dbbbg,MATCH($A19,db00!$A$3:$A$1611,0),14) -> 4.1915296 | K19: =INDEX(dbbbg,MATCH($A19,db00!$A$3:$A$1611,0),9) -> 13742 | L19: =INDEX(dbbbg,MATCH($A19,db00!$A$3:$A$1611,0),10) -> 1.562 | M19: =INDEX(dbbbg,MATCH($A19,db00!$A$3:$A$1611,0),11) -> 1576.73 | N19: =INDEX(dbbbg,MATCH($A19,db00!$A$3:$A$1611,0),12) -> 2.68 | O19: =D19-E19 -> 0.173 | P19: =E19-L19 -> -0.207 | Q19: =INDEX(cds,MATCH($A19,cds!$I$3:$I$4708,0),5) -> 65.615 | R19: =INDEX(idyield,MATCH($A19,yieldid!$A$3:$A$4130,0),12) -> 6.949604 | S19: =C19*D19 -> 30.848657 | T19: =F19*G19 -> 1308.3957 | U19: 7.38714 | V19: 14 | W19: 2 | X19: 3.0712444 | Y19: 6910300 | Z19: 2250000 | AA19: 7.4 | AB19: 7.35
A20: 43865 | B20: bm30 | C20: 28.271047 | D20: =INDEX(dbbbg,MATCH($A20,db00!$A$3:$A$1611,0),2) -> 1.528 | E20: =INDEX(dbbbg,MATCH($A20,db00!$A$3:$A$1611,0),3) -> 1.355 | F20: =INDEX(dbbbg,MATCH($A20,db00!$A$3:$A$1611,0),4) -> 17.97 | G20: =INDEX(dbbbg,MATCH($A20,db00!$A$3:$A$1611,0),5) -> 72.81 | H20: =INDEX(dbbbg,MATCH($A20,db00!$A$3:$A$1611,0),6) -> 97.8 | I20: =INDEX(dbbbg,MATCH($A20,db00!$A$3:$A$1611,0),13) -> 0.32746325 | J20: =INDEX(dbbbg,MATCH($A20,db00!$A$3:$A$1611,0),14) -> 4.1915296 | K20: =INDEX(dbbbg,MATCH($A20,db00!$A$3:$A$1611,0),9) -> 13742 | L20: =INDEX(dbbbg,MATCH($A20,db00!$A$3:$A$1611,0),10) -> 1.562 | M20: =INDEX(dbbbg,MATCH($A20,db00!$A$3:$A$1611,0),11) -> 1576.73 | N20: =INDEX(dbbbg,MATCH($A20,db00!$A$3:$A$1611,0),12) -> 2.68 | O20: =D20-E20 -> 0.173 | P20: =E20-L20 -> -0.207 | Q20: =INDEX(cds,MATCH($A20,cds!$I$3:$I$4708,0),5) -> 65.615 | R20: =INDEX(idyield,MATCH($A20,yieldid!$A$3:$A$4130,0),12) -> 6.949604 | S20: =C20*D20 -> 43.19816 | T20: =F20*G20 -> 1308.3957 | U20: 7.58645 | V20: 14 | W20: 2 | X20: 1.8962857 | Y20: 5309600 | Z20: 2800000 | AA20: 7.6 | AB20: 7.58
... A47: 43921 | B47: bm20 | C47: 20.035592 | D47: =INDEX(dbbbg,MATCH($A47,db00!$A$3:$A$1611,0),2) -> 0.729 | E47: =INDEX(dbbbg,MATCH($A47,db00!$A$3:$A$1611,0),3) -> 0.23 | F47: =INDEX(dbbbg,MATCH($A47,db00!$A$3:$A$1611,0),4) -> 57.08 | G47: =INDEX(dbbbg,MATCH($A47,db00!$A$3:$A$1611,0),5) -> 90.7 | H47: =INDEX(dbbbg,MATCH($A47,db00!$A$3:$A$1611,0),6) -> 99.181 | I47: =INDEX(dbbbg,MATCH($A47,db00!$A$3:$A$1611,0),13) -> 0.58758722 | J47: =INDEX(dbbbg,MATCH($A47,db00!$A$3:$A$1611,0),14) -> 6.0350104 | K47: =INDEX(dbbbg,MATCH($A47,db00!$A$3:$A$1611,0),9) -> 16338 | L47: =INDEX(dbbbg,MATCH($A47,db00!$A$3:$A$1611,0),10) -> 0.044 | M47: =INDEX(dbbbg,MATCH($A47,db00!$A$3:$A$1611,0),11) -> 1622.51 | N47: =INDEX(dbbbg,MATCH($A47,db00!$A$3:$A$1611,0),12) -> 2.96 | O47: =D47-E47 -> 0.499 | P47: =E47-L47 -> 0.186 | Q47: =INDEX(cds,MATCH($A47,cds!$I$3:$I$4708,0),5) -> 227.565 | R47: =INDEX(idyield,MATCH($A47,yieldid!$A$3:$A$4130,0),12) -> 8.232128 | S47: =C47*D47 -> 14.605947 | T47: =F47*G47 -> 5177.156 | U47: 7.83695 | V47: 14 | W47: 6 | X47: 2.1063333 | Y47: 1263800 | Z47: 600000 | AA47: 7.84 | AB47: 8.35
A48: 43921 | B48: bm30 | C48: 28.117728 | D48: =INDEX(dbbbg,MATCH($A48,db00!$A$3:$A$1611,0),2) -> 0.729 | E48: =INDEX(dbbbg,MATCH($A48,db00!$A$3:$A$1611,0),3) -> 0.23 | F48: =INDEX(dbbbg,MATCH($A48,db00!$A$3:$A$1611,0),4) -> 57.08 | G48: =INDEX(dbbbg,MATCH($A48,db00!$A$3:$A$1611,0),5) -> 90.7 | H48: =INDEX(dbbbg,MATCH($A48,db00!$A$3:$A$1611,0),6) -> 99.181 | I48: =INDEX(dbbbg,MATCH($A48,db00!$A$3:$A$1611,0),13) -> 0.58758722 | J48: =INDEX(dbbbg,MATCH($A48,db00!$A$3:$A$1611,0),14) -> 6.0350104 | K48: =INDEX(dbbbg,MATCH($A48,db00!$A$3:$A$1611,0),9) -> 16338 | L48: =INDEX(dbbbg,MATCH($A48,db00!$A$3:$A$1611,0),10) -> 0.044 | M48: =INDEX(dbbbg,MATCH($A48,db00!$A$3:$A$1611,0),11) -> 1622.51 | N48: =INDEX(dbbbg,MATCH($A48,db00!$A$3:$A$1611,0),12) -> 2.96 | O48: =D48-E48 -> 0.499 | P48: =E48-L48 -> 0.186 | Q48: =INDEX(cds,MATCH($A48,cds!$I$3:$I$4708,0),5) -> 227.565 | R48: =INDEX(idyield,MATCH($A48,yieldid!$A$3:$A$4130,0),12) -> 8.232128 | S48: =C48*D48 -> 20.497823 | T48: =F48*G48 -> 5177.156 | V48: 14 | W48: 6 | X48: 2.4610753 | Y48: 755500 | AA48: 7.85 | AB48: 8.45
A49: 43921 | B49: spn03m | C49: 0.25188227 | D49: =INDEX(dbbbg,MATCH($A49,db00!$A$3:$A$1611,0),2) -> 0.729 | E49: =INDEX(dbbbg,MATCH($A49,db00!$A$3:$A$1611,0),3) -> 0.23 | F49: =INDEX(dbbbg,MATCH($A49,db00!$A$3:$A$1611,0),4) -> 57.08 | G49: =INDEX(dbbbg,MATCH($A49,db00!$A$3:$A$1611,0),5) -> 90.7 | H49: =INDEX(dbbbg,MATCH($A49,db00!$A$3:$A$1611,0),6) -> 99.181 | I49: =INDEX(dbbbg,MATCH($A49,db00!$A$3:$A$1611,0),13) -> 0.58758722 | J49: =INDEX(dbbbg,MATCH($A49,db00!$A$3:$A$1611,0),14) -> 6.0350104 | K49: =INDEX(dbbbg,MATCH($A49,db00!$A$3:$A$1611,0),9) -> 16338 | L49: =INDEX(dbbbg,MATCH($A49,db00!$A$3:$A$1611,0),10) -> 0.044 | M49: =INDEX(dbbbg,MATCH($A49,db00!$A$3:$A$1611,0),11) -> 1622.51 | N49: =INDEX(dbbbg,MATCH($A49,db00!$A$3:$A$1611,0),12) -> 2.96 | O49: =D49-E49 -> 0.499 | P49: =E49-L49 -> 0.186 | Q49: =INDEX(cds,MATCH($A49,cds!$I$3:$I$4708,0),5) -> 227.565 | R49: =INDEX(idyield,MATCH($A49,yieldid!$A$3:$A$4130,0),12) -> 8.232128 | S49: =C49*D49 -> 0.18362218 | T49: =F49*G49 -> 5177.156 | U49: 2.76529 | V49: 14 | W49: 6 | X49: 3.6258065 | Y49: 11240000 | Z49: 3100000 | AA49: 2.94 | AB49: 2.55
A50: 43921 | B50: spn12m | C50: 0.99657769 | D50: =INDEX(dbbbg,MATCH($A50,db00!$A$3:$A$1611,0),2) -> 0.729 | E50: =INDEX(dbbbg,MATCH($A50,db00!$A$3:$A$1611,0),3) -> 0.23 | F50: =INDEX(dbbbg,MATCH($A50,db00!$A$3:$A$1611,0),4) -> 57.08 | G50: =INDEX(dbbbg,MATCH($A50,db00!$A$3:$A$1611,0),5) -> 90.7 | H50: =INDEX(dbbbg,MATCH($A50,db00!$A$3:$A$1611,0),6) -> 99.181 | I50: =INDEX(dbbbg,MATCH($A50,db00!$A$3:$A$1611,0),13) -> 0.58758722 | J50: =INDEX(dbbbg,MATCH($A50,db00!$A$3:$A$1611,0),14) -> 6.0350104 | K50: =INDEX(dbbbg,MATCH($A50,db00!$A$3:$A$1611,0),9) -> 16338 | L50: =INDEX(dbbbg,MATCH($A50,db00!$A$3:$A$1611,0),10) -> 0.044 | M50: =INDEX(dbbbg,MATCH($A50,db00!$A$3:$A$1611,0),11) -> 1622.51 | N50: =INDEX(dbbbg,MATCH($A50,db00!$A$3:$A$1611,0),12) -> 2.96 | O50: =D50-E50 -> 0.499 | P50: =E50-L50 -> 0.186 | Q50: =INDEX(cds,MATCH($A50,cds!$I$3:$I$4708,0),5) -> 227.565 | R50: =INDEX(idyield,MATCH($A50,yieldid!$A$3:$A$4130,0),12) -> 8.232128 | S50: =C50*D50 -> 0.72650513 | T50: =F50*G50 -> 5177.156 | U50: 3.35156 | V50: 14 | W50: 6 | X50: 2.84375 | Y50: 18200000 | Z50: 6400000 | AA50: 3.36 | AB50: 3.45
A51: 43935 | B51: bm05 | C51: 5.1635866 | D51: =INDEX(dbbbg,MATCH($A51,db00!$A$3:$A$1611,0),2) -> 0.774 | E51: =INDEX(dbbbg,MATCH($A51,db00!$A$3:$A$1611,0),3) -> 0.248 | F51: =INDEX(dbbbg,MATCH($A51,db00!$A$3:$A$1611,0),4) -> 41.17 | G51: =INDEX(dbbbg,MATCH($A51,db00!$A$3:$A$1611,0),5) -> 75.85 | H51: =INDEX(dbbbg,MATCH($A51,db00!$A$3:$A$1611,0),6) -> 99.348 | I51: =INDEX(dbbbg,MATCH($A51,db00!$A$3:$A$1611,0),13) -> 1.4523353 | J51: =INDEX(dbbbg,MATCH($A51,db00!$A$3:$A$1611,0),14) -> 7.6647473 | K51: =INDEX(dbbbg,MATCH($A51,db00!$A$3:$A$1611,0),9) -> 15630 | L51: =INDEX(dbbbg,MATCH($A51,db00!$A$3:$A$1611,0),10) -> 0.214 | M51: =INDEX(dbbbg,MATCH($A51,db00!$A$3:$A$1611,0),11) -> 1715.34 | N51: =INDEX(dbbbg,MATCH($A51,db00!$A$3:$A$1611,0),12) -> 2.96 | O51: =D51-E51 -> 0.526 | P51: =E51-L51 -> 0.034 | Q51: =INDEX(cds,MATCH($A51,cds!$I$3:$I$4708,0),5) -> 205.97 | R51: =INDEX(idyield,MATCH($A51,yieldid!$A$3:$A$4130,0),12) -> 8.345818 | S51: =C51*D51 -> 3.996616 | T51: =F51*G51 -> 3122.7445 | U51: 7.15431 | V51: 14 | W51: 7 | X51: 1.182875 | Y51: 9463000 | Z51: 8000000 | AA51: 7.23 | AB51: 7.59
A52: 43935 | B52: bm10 | C52: 10.414784 | D52: =INDEX(dbbbg,MATCH($A52,db00!$A$3:$A$1611,0),2) -> 0.774 | E52: =INDEX(dbbbg,MATCH($A52,db00!$A$3:$A$1611,0),3) -> 0.248 | F52: =INDEX(dbbbg,MATCH($A52,db00!$A$3:$A$1611,0),4) -> 41.17 | G52: =INDEX(dbbbg,MATCH($A52,db00!$A$3:$A$1611,0),5) -> 75.85 | H52: =INDEX(dbbbg,MATCH($A52,db00!$A$3:$A$1611,0),6) -> 99.348 | I52: =INDEX(dbbbg,MATCH($A52,db00!$A$3:$A$1611,0),13) -> 1.4523353 | J52: =INDEX(dbbbg,MATCH($A52,db00!$A$3:$A$1611,0),14) -> 7.6647473 | K52: =INDEX(dbbbg,MATCH($A52,db00!$A$3:$A$1611,0),9) -> 15630 | L52: =INDEX(dbbbg,MATCH($A52,db00!$A$3:$A$1611,0),10) -> 0.214 | M52: =INDEX(dbbbg,MATCH($A52,db00!$A$3:$A$1611,0),11) -> 1715.34 | N52: =INDEX(dbbbg,MATCH($A52,db00!$A$3:$A$1611,0),12) -> 2.96 | O52: =D52-E52 -> 0.526 | P52: =E52-L52 -> 0.034 | Q52: =INDEX(cds,MATCH($A52,cds!$I$3:$I$4708,0),5) -> 205.97 | R52: =INDEX(idyield,MATCH($A52,yieldid!$A$3:$A$4130,0),12) -> 8.345818 | S52: =C52*D52 -> 8.0610431 | T52: =F52*G52 -> 3122.7445 | U52: 7.82987 | V52: 14 | W52: 7 | X52: 1.3408661 | Y52: 8514500 | Z52: 6350000 | AA52: 7.83 | AB52: 8
A53: 43935 | B53: bm15 | C53: 15.162218 | D53: =INDEX(dbbbg,MATCH($A53,db00!$A$3:$A$1611,0),2) -> 0.774 | E53: =INDEX(dbbbg,MATCH($A53,db00!$A$3:$A$1611,0),3) -> 0.248 | F53: =INDEX(dbbbg,MATCH($A53,db00!$A$3:$A$1611,0),4) -> 41.17 | G53: =INDEX(dbbbg,MATCH($A53,db00!$A$3:$A$1611,0),5) -> 75.85 | H53: =INDEX(dbbbg,MATCH($A53,db00!$A$3:$A$1611,0),6) -> 99.348 | I53: =INDEX(dbbbg,MATCH($A53,db00!$A$3:$A$1611,0),13) -> 1.4523353 | J53: =INDEX(dbbbg,MATCH($A53,db00!$A$3:$A$1611,0),14) -> 7.6647473 | K53: =INDEX(dbbbg,MATCH($A53,db00!$A$3:$A$1611,0),9) -> 15630 | L53: =INDEX(dbbbg,MATCH($A53,db00!$A$3:$A$1611,0),10) -> 0.214 | M53: =INDEX(dbbbg,MATCH($A53,db00!$A$3:$A$1611,0),11) -> 1715.34 | N53: =INDEX(dbbbg,MATCH($A53,db00!$A$3:$A$1611,0),12) -> 2.96 | O53: =D53-E53 -> 0.526 | P53: =E53-L53 -> 0.034 | Q53: =INDEX(cds,MATCH($A53,cds!$I$3:$I$4708,0),5) -> 205.97 | R53: =INDEX(idyield,MATCH($A53,yieldid!$A$3:$A$4130,0),12) -> 8.345818 | S53: =C53*D53 -> 11.735556 | T53: =F53*G53 -> 3122.7445 | U53: 8.22995 | V53: 14 | W53: 7 | X53: 1.49825 | Y53: 3595800 | Z53: 2400000 | AA53: 8.23 | AB53: 8.25
A54: 43935 | B54: bm20 | C54: 19.997262 | D54: =INDEX(dbbbg,MATCH($A54,db00!$A$3:$A$1611,0),2) -> 0.774 | E54: =INDEX(dbbbg,MATCH($A54,db00!$A$3:$A$1611,0),3) -> 0.248 | F54: =INDEX(dbbbg,MATCH($A54,db00!$A$3:$A$1611,0),4) -> 41.17 | G54: =INDEX(dbbbg,MATCH($A54,db00!$A$3:$A$1611,0),5) -> 75.85 | H54: =INDEX(dbbbg,MATCH($A54,db00!$A$3:$A$1611,0),6) -> 99.348 | I54: =INDEX(dbbbg,MATCH($A54,db00!$A$3:$A$1611,0),13) -> 1.4523353 | J54: =INDEX(dbbbg,MATCH($A54,db00!$A$3:$A$1611,0),14) -> 7.6647473 | K54: =INDEX(dbbbg,MATCH($A54,db00!$A$3:$A$1611,0),9) -> 15630 | L54: =INDEX(dbbbg,MATCH($A54,db00!$A$3:$A$1611,0),10) -> 0.214 | M54: =INDEX(dbbbg,MATCH($A54,db00!$A$3:$A$1611,0),11) -> 1715.34 | N54: =INDEX(dbbbg,MATCH($A54,db00!$A$3:$A$1611,0),12) -> 2.96 | O54: =D54-E54 -> 0.526 | P54: =E54-L54 -> 0.034 | Q54: =INDEX(cds,MATCH($A54,cds!$I$3:$I$4708,0),5) -> 205.97 | R54: =INDEX(idyield,MATCH($A54,yieldid!$A$3:$A$4130,0),12) -> 8.345818 | S54: =C54*D54 -> 15.477881 | T54: =F54*G54 -> 3122.7445 | U54: 8.33942 | V54: 14 | W54: 7 | X54: 1.7492941 | Y54: 1486900 | Z54: 850000 | AA54: 8.35 | AB54: 8.32
A55: 43935 | B55: bm30 | C55: 28.079398 | D55: =INDEX(dbbbg,MATCH($A55,db00!$A$3:$A$1611,0),2) -> 0.774 | E55: =INDEX(dbbbg,MATCH($A55,db00!$A$3:$A$1611,0),3) -> 0.248 | F55: =INDEX(dbbbg,MATCH($A55,db00!$A$3:$A$1611,0),4) -> 41.17 | G55: =INDEX(dbbbg,MATCH($A55,db00!$A$3:$A$1611,0),5) -> 75.85 | H55: =INDEX(dbbbg,MATCH($A55,db00!$A$3:$A$1611,0),6) -> 99.348 | I55: =INDEX(dbbbg,MATCH($A55,db00!$A$3:$A$1611,0),13) -> 1.4523353 | J55: =INDEX(dbbbg,MATCH($A55,db00!$A$3:$A$1611,0),14) -> 7.6647473 | K55: =INDEX(dbbbg,MATCH($A55,db00!$A$3:$A$1611,0),9) -> 15630 | L55: =INDEX(dbbbg,MATCH($A55,db00!$A$3:$A$1611,0),10) -> 0.214 | M55: =INDEX(dbbbg,MATCH($A55,db00!$A$3:$A$1611,0),11) -> 1715.34 | N55: =INDEX(dbbbg,MATCH($A55,db00!$A$3:$A$1611,0),12) -> 2.96 | O55: =D55-E55 -> 0.526 | P55: =E55-L55 -> 0.034 | Q55: =INDEX(cds,MATCH($A55,cds!$I$3:$I$4708,0),5) -> 205.97 | R55: =INDEX(idyield,MATCH($A55,yieldid!$A$3:$A$4130,0),12) -> 8.345818 | S55: =C55*D55 -> 21.733454 | T55: =F55*G55 -> 3122.7445 | V55: 14 | W55: 7 | X55: 2.4610753 | Y55: 264800 | AA55: 8.45 | AB55: 8.43
